package com.hexi.kotlindemo

import kotlinx.coroutines.*
import org.junit.Test
import java.io.IOException

class ExceptionTest {
    @Test
    fun test0() = runBlocking {
        val job = GlobalScope.launch {
            println("Throwing exception from launch")
            throw IndexOutOfBoundsException() // 我们将在控制台打印 Thread.defaultUncaughtExceptionHandler
        }
        job.join()
        println("Joined failed job")
        val deferred = GlobalScope.async {
            println("Throwing exception from async")
            throw ArithmeticException() // 没有打印任何东西，依赖用户去调用等待
        }
        try {
            deferred.await()
            println("Unreached")
        } catch (e: ArithmeticException) {
            println("Caught ArithmeticException")
        }
    }

    @Test
    fun test1() = runBlocking {
        val job = launch {
            val child = launch {
                try {
                    delay(Long.MAX_VALUE)
                } finally {
                    println("Child is cancelled")
                }
            }
            println("Before yield time: ${System.currentTimeMillis()}")
            yield()
            println("Cancelling child time: ${System.currentTimeMillis()}")
            child.cancel()
            child.join()
            yield()
            println("Parent is not cancelled")
        }
        job.join()
    }

    @Test
    fun test2() = runBlocking {
        val handler = CoroutineExceptionHandler { _, exception ->
            println("Caught $exception")
        }
        val job = GlobalScope.launch(handler) {
            throw AssertionError()
        }
        val deferred = GlobalScope.async(handler) {
            throw ArithmeticException() // 没有打印任何东西，依赖用户去调用 deferred.await()
        }
        joinAll(job, deferred)
    }

    @Test
    fun test3() = runBlocking {
        val handler = CoroutineExceptionHandler { _, exception ->
            println("Caught $exception")
        }
        val job = GlobalScope.launch(handler) {
            launch { // 第一个子协程
                try {
                    delay(Long.MAX_VALUE)
                } finally {
                    withContext(NonCancellable) {
                        println("Children are cancelled, but exception is not handled until all children terminate")
                        delay(100)
                        println("The first child finished its non cancellable block")
                    }
                }
            }
            launch { // 第二个子协程
                delay(10)
                println("Second child throws an exception")
                throw ArithmeticException()
            }
        }
        job.join()
    }

    @Test
    fun test5() = runBlocking {
        val handler = CoroutineExceptionHandler { _, exception ->
            println("Caught $exception with suppressed ${exception.suppressed.contentToString()}")
        }
        val job = GlobalScope.launch(handler) {
            launch {
                try {
                    delay(Long.MAX_VALUE)
                } finally {
                    throw ArithmeticException()
                }
            }
            launch {
                delay(100)
                throw IOException()
            }
            delay(Long.MAX_VALUE)
        }
        job.join()
    }

    @Test
    fun test6() = runBlocking {
        val handler = CoroutineExceptionHandler { _, exception ->
            println("Caught original $exception")
        }
        val job = GlobalScope.launch(handler) {
            val inner = launch {
                launch {
                    launch {
                        throw IOException()
                    }
                }
            }
            try {
                inner.join()
            } catch (e: CancellationException) {
                println("Rethrowing CancellationException with original cause")
                throw e
            }
        }
        job.join()
    }
}